2024-12-18 10:05:03.225 WARNING (SyncWorker_0) [homeassistant.loader] We found a custom integration presence_simulation which has not been tested by Home Assistant. This component might cause stability problems, be sure to disable it if you experience issues with Home Assistant
2024-12-18 10:05:03.228 WARNING (SyncWorker_0) [homeassistant.loader] We found a custom integration iphonedetect which has not been tested by Home Assistant. This component might cause stability problems, be sure to disable it if you experience issues with Home Assistant
2024-12-18 10:05:03.232 WARNING (SyncWorker_0) [homeassistant.loader] We found a custom integration pirateweather which has not been tested by Home Assistant. This component might cause stability problems, be sure to disable it if you experience issues with Home Assistant
2024-12-18 10:05:03.233 WARNING (SyncWorker_0) [homeassistant.loader] We found a custom integration alexa_media which has not been tested by Home Assistant. This component might cause stability problems, be sure to disable it if you experience issues with Home Assistant
2024-12-18 10:05:03.235 WARNING (SyncWorker_0) [homeassistant.loader] We found a custom integration simple_wyze_vac which has not been tested by Home Assistant. This component might cause stability problems, be sure to disable it if you experience issues with Home Assistant
2024-12-18 10:05:03.237 WARNING (SyncWorker_0) [homeassistant.loader] We found a custom integration hacs which has not been tested by Home Assistant. This component might cause stability problems, be sure to disable it if you experience issues with Home Assistant
2024-12-18 10:05:03.241 WARNING (SyncWorker_0) [homeassistant.loader] We found a custom integration gasbuddy which has not been tested by Home Assistant. This component might cause stability problems, be sure to disable it if you experience issues with Home Assistant
2024-12-18 10:05:03.242 WARNING (SyncWorker_0) [homeassistant.loader] We found a custom integration reolink_discovery which has not been tested by Home Assistant. This component might cause stability problems, be sure to disable it if you experience issues with Home Assistant
2024-12-18 10:05:03.244 WARNING (SyncWorker_0) [homeassistant.loader] We found a custom integration wyzeapi which has not been tested by Home Assistant. This component might cause stability problems, be sure to disable it if you experience issues with Home Assistant
2024-12-18 10:05:03.245 WARNING (SyncWorker_0) [homeassistant.loader] We found a custom integration auto_backup which has not been tested by Home Assistant. This component might cause stability problems, be sure to disable it if you experience issues with Home Assistant
2024-12-18 10:05:08.025 WARNING (MainThread) [homeassistant.helpers.translation] Failed to load integration for translation: Integration 'zwave' not found.
2024-12-18 10:05:13.728 ERROR (MainThread) [homeassistant.setup] Setup failed for 'zwave': Integration not found.
2024-12-18 10:05:29.259 ERROR (SyncWorker_2) [homeassistant.components.influxdb] Cannot connect to InfluxDB due to 'HTTPConnectionPool(host='localhost', port=8086): Max retries exceeded with url: /write?db=home_assistant (Caused by NewConnectionError('<urllib3.connection.HTTPConnection object at 0x7a2a38a63250>: Failed to establish a new connection: [Errno 111] Connection refused'))'. Please check that the provided connection details (host, port, etc.) are correct and that your InfluxDB server is running and accessible. Retrying in 60 seconds.
2024-12-18 10:05:43.694 ERROR (MainThread) [homeassistant.components.sensor] Platform smartthings does not generate unique IDs. ID 1a6d0984-19b4-426e-86d8-77906f2fe112.energy already exists - ignoring sensor.outlet_energy_meter
2024-12-18 10:05:43.695 ERROR (MainThread) [homeassistant.components.sensor] Platform smartthings does not generate unique IDs. ID 1a6d0984-19b4-426e-86d8-77906f2fe112.power already exists - ignoring sensor.outlet_power_meter
2024-12-18 10:06:29.332 ERROR (SyncWorker_5) [homeassistant.components.influxdb] Cannot connect to InfluxDB due to 'HTTPConnectionPool(host='localhost', port=8086): Max retries exceeded with url: /write?db=home_assistant (Caused by NewConnectionError('<urllib3.connection.HTTPConnection object at 0x7a2a2ba24410>: Failed to establish a new connection: [Errno 111] Connection refused'))'. Please check that the provided connection details (host, port, etc.) are correct and that your InfluxDB server is running and accessible. Retrying in 60 seconds.
2024-12-18 10:07:29.388 ERROR (SyncWorker_0) [homeassistant.components.influxdb] Cannot connect to InfluxDB due to 'HTTPConnectionPool(host='localhost', port=8086): Max retries exceeded with url: /write?db=home_assistant (Caused by NewConnectionError('<urllib3.connection.HTTPConnection object at 0x7a2a35d6e8a0>: Failed to establish a new connection: [Errno 111] Connection refused'))'. Please check that the provided connection details (host, port, etc.) are correct and that your InfluxDB server is running and accessible. Retrying in 60 seconds.
2024-12-18 10:08:29.423 ERROR (SyncWorker_3) [homeassistant.components.influxdb] Cannot connect to InfluxDB due to 'HTTPConnectionPool(host='localhost', port=8086): Max retries exceeded with url: /write?db=home_assistant (Caused by NewConnectionError('<urllib3.connection.HTTPConnection object at 0x7a2a4d0d3c50>: Failed to establish a new connection: [Errno 111] Connection refused'))'. Please check that the provided connection details (host, port, etc.) are correct and that your InfluxDB server is running and accessible. Retrying in 60 seconds.
2024-12-18 10:09:29.475 ERROR (SyncWorker_6) [homeassistant.components.influxdb] Cannot connect to InfluxDB due to 'HTTPConnectionPool(host='localhost', port=8086): Max retries exceeded with url: /write?db=home_assistant (Caused by NewConnectionError('<urllib3.connection.HTTPConnection object at 0x7a2a4d0d0d70>: Failed to establish a new connection: [Errno 111] Connection refused'))'. Please check that the provided connection details (host, port, etc.) are correct and that your InfluxDB server is running and accessible. Retrying in 60 seconds.
2024-12-18 10:10:29.535 ERROR (SyncWorker_1) [homeassistant.components.influxdb] Cannot connect to InfluxDB due to 'HTTPConnectionPool(host='localhost', port=8086): Max retries exceeded with url: /write?db=home_assistant (Caused by NewConnectionError('<urllib3.connection.HTTPConnection object at 0x7a2a2ba27980>: Failed to establish a new connection: [Errno 111] Connection refused'))'. Please check that the provided connection details (host, port, etc.) are correct and that your InfluxDB server is running and accessible. Retrying in 60 seconds.
2024-12-18 10:11:29.569 ERROR (SyncWorker_3) [homeassistant.components.influxdb] Cannot connect to InfluxDB due to 'HTTPConnectionPool(host='localhost', port=8086): Max retries exceeded with url: /write?db=home_assistant (Caused by NewConnectionError('<urllib3.connection.HTTPConnection object at 0x7a2a2c4ae120>: Failed to establish a new connection: [Errno 111] Connection refused'))'. Please check that the provided connection details (host, port, etc.) are correct and that your InfluxDB server is running and accessible. Retrying in 60 seconds.
2024-12-18 10:12:29.607 ERROR (SyncWorker_2) [homeassistant.components.influxdb] Cannot connect to InfluxDB due to 'HTTPConnectionPool(host='localhost', port=8086): Max retries exceeded with url: /write?db=home_assistant (Caused by NewConnectionError('<urllib3.connection.HTTPConnection object at 0x7a2a24508b90>: Failed to establish a new connection: [Errno 111] Connection refused'))'. Please check that the provided connection details (host, port, etc.) are correct and that your InfluxDB server is running and accessible. Retrying in 60 seconds.
2024-12-18 10:13:29.662 ERROR (SyncWorker_5) [homeassistant.components.influxdb] Cannot connect to InfluxDB due to 'HTTPConnectionPool(host='localhost', port=8086): Max retries exceeded with url: /write?db=home_assistant (Caused by NewConnectionError('<urllib3.connection.HTTPConnection object at 0x7a2a2c4ace60>: Failed to establish a new connection: [Errno 111] Connection refused'))'. Please check that the provided connection details (host, port, etc.) are correct and that your InfluxDB server is running and accessible. Retrying in 60 seconds.
2024-12-18 10:14:29.708 ERROR (SyncWorker_1) [homeassistant.components.influxdb] Cannot connect to InfluxDB due to 'HTTPConnectionPool(host='localhost', port=8086): Max retries exceeded with url: /write?db=home_assistant (Caused by NewConnectionError('<urllib3.connection.HTTPConnection object at 0x7a2a2c4ac320>: Failed to establish a new connection: [Errno 111] Connection refused'))'. Please check that the provided connection details (host, port, etc.) are correct and that your InfluxDB server is running and accessible. Retrying in 60 seconds.
2024-12-18 10:15:29.761 ERROR (SyncWorker_1) [homeassistant.components.influxdb] Cannot connect to InfluxDB due to 'HTTPConnectionPool(host='localhost', port=8086): Max retries exceeded with url: /write?db=home_assistant (Caused by NewConnectionError('<urllib3.connection.HTTPConnection object at 0x7a2a29ced040>: Failed to establish a new connection: [Errno 111] Connection refused'))'. Please check that the provided connection details (host, port, etc.) are correct and that your InfluxDB server is running and accessible. Retrying in 60 seconds.
2024-12-18 10:16:29.818 ERROR (SyncWorker_7) [homeassistant.components.influxdb] Cannot connect to InfluxDB due to 'HTTPConnectionPool(host='localhost', port=8086): Max retries exceeded with url: /write?db=home_assistant (Caused by NewConnectionError('<urllib3.connection.HTTPConnection object at 0x7a2a29cef4d0>: Failed to establish a new connection: [Errno 111] Connection refused'))'. Please check that the provided connection details (host, port, etc.) are correct and that your InfluxDB server is running and accessible. Retrying in 60 seconds.
2024-12-18 10:17:29.859 ERROR (SyncWorker_3) [homeassistant.components.influxdb] Cannot connect to InfluxDB due to 'HTTPConnectionPool(host='localhost', port=8086): Max retries exceeded with url: /write?db=home_assistant (Caused by NewConnectionError('<urllib3.connection.HTTPConnection object at 0x7a2a29cef3e0>: Failed to establish a new connection: [Errno 111] Connection refused'))'. Please check that the provided connection details (host, port, etc.) are correct and that your InfluxDB server is running and accessible. Retrying in 60 seconds.
2024-12-18 10:18:29.913 ERROR (SyncWorker_0) [homeassistant.components.influxdb] Cannot connect to InfluxDB due to 'HTTPConnectionPool(host='localhost', port=8086): Max retries exceeded with url: /write?db=home_assistant (Caused by NewConnectionError('<urllib3.connection.HTTPConnection object at 0x7a2a29ced400>: Failed to establish a new connection: [Errno 111] Connection refused'))'. Please check that the provided connection details (host, port, etc.) are correct and that your InfluxDB server is running and accessible. Retrying in 60 seconds.
2024-12-18 10:19:29.967 ERROR (SyncWorker_7) [homeassistant.components.influxdb] Cannot connect to InfluxDB due to 'HTTPConnectionPool(host='localhost', port=8086): Max retries exceeded with url: /write?db=home_assistant (Caused by NewConnectionError('<urllib3.connection.HTTPConnection object at 0x7a2a29ced5e0>: Failed to establish a new connection: [Errno 111] Connection refused'))'. Please check that the provided connection details (host, port, etc.) are correct and that your InfluxDB server is running and accessible. Retrying in 60 seconds.
2024-12-18 10:20:30.003 ERROR (SyncWorker_15) [homeassistant.components.influxdb] Cannot connect to InfluxDB due to 'HTTPConnectionPool(host='localhost', port=8086): Max retries exceeded with url: /write?db=home_assistant (Caused by NewConnectionError('<urllib3.connection.HTTPConnection object at 0x7a2a29cec9b0>: Failed to establish a new connection: [Errno 111] Connection refused'))'. Please check that the provided connection details (host, port, etc.) are correct and that your InfluxDB server is running and accessible. Retrying in 60 seconds.
2024-12-18 10:21:30.055 ERROR (SyncWorker_1) [homeassistant.components.influxdb] Cannot connect to InfluxDB due to 'HTTPConnectionPool(host='localhost', port=8086): Max retries exceeded with url: /write?db=home_assistant (Caused by NewConnectionError('<urllib3.connection.HTTPConnection object at 0x7a2a417d6a80>: Failed to establish a new connection: [Errno 111] Connection refused'))'. Please check that the provided connection details (host, port, etc.) are correct and that your InfluxDB server is running and accessible. Retrying in 60 seconds.
2024-12-18 10:22:30.093 ERROR (SyncWorker_10) [homeassistant.components.influxdb] Cannot connect to InfluxDB due to 'HTTPConnectionPool(host='localhost', port=8086): Max retries exceeded with url: /write?db=home_assistant (Caused by NewConnectionError('<urllib3.connection.HTTPConnection object at 0x7a2a242bdf40>: Failed to establish a new connection: [Errno 111] Connection refused'))'. Please check that the provided connection details (host, port, etc.) are correct and that your InfluxDB server is running and accessible. Retrying in 60 seconds.
2024-12-18 10:23:30.137 ERROR (SyncWorker_4) [homeassistant.components.influxdb] Cannot connect to InfluxDB due to 'HTTPConnectionPool(host='localhost', port=8086): Max retries exceeded with url: /write?db=home_assistant (Caused by NewConnectionError('<urllib3.connection.HTTPConnection object at 0x7a2a242bd5e0>: Failed to establish a new connection: [Errno 111] Connection refused'))'. Please check that the provided connection details (host, port, etc.) are correct and that your InfluxDB server is running and accessible. Retrying in 60 seconds.
2024-12-18 10:24:30.182 ERROR (SyncWorker_22) [homeassistant.components.influxdb] Cannot connect to InfluxDB due to 'HTTPConnectionPool(host='localhost', port=8086): Max retries exceeded with url: /write?db=home_assistant (Caused by NewConnectionError('<urllib3.connection.HTTPConnection object at 0x7a2a242bf890>: Failed to establish a new connection: [Errno 111] Connection refused'))'. Please check that the provided connection details (host, port, etc.) are correct and that your InfluxDB server is running and accessible. Retrying in 60 seconds.
2024-12-18 10:25:30.217 ERROR (SyncWorker_8) [homeassistant.components.influxdb] Cannot connect to InfluxDB due to 'HTTPConnectionPool(host='localhost', port=8086): Max retries exceeded with url: /write?db=home_assistant (Caused by NewConnectionError('<urllib3.connection.HTTPConnection object at 0x7a2a242be120>: Failed to establish a new connection: [Errno 111] Connection refused'))'. Please check that the provided connection details (host, port, etc.) are correct and that your InfluxDB server is running and accessible. Retrying in 60 seconds.
2024-12-18 10:26:30.267 ERROR (SyncWorker_12) [homeassistant.components.influxdb] Cannot connect to InfluxDB due to 'HTTPConnectionPool(host='localhost', port=8086): Max retries exceeded with url: /write?db=home_assistant (Caused by NewConnectionError('<urllib3.connection.HTTPConnection object at 0x7a2a242be4e0>: Failed to establish a new connection: [Errno 111] Connection refused'))'. Please check that the provided connection details (host, port, etc.) are correct and that your InfluxDB server is running and accessible. Retrying in 60 seconds.
2024-12-18 10:27:30.292 ERROR (SyncWorker_6) [homeassistant.components.influxdb] Cannot connect to InfluxDB due to 'HTTPConnectionPool(host='localhost', port=8086): Max retries exceeded with url: /write?db=home_assistant (Caused by NewConnectionError('<urllib3.connection.HTTPConnection object at 0x7a2a242be210>: Failed to establish a new connection: [Errno 111] Connection refused'))'. Please check that the provided connection details (host, port, etc.) are correct and that your InfluxDB server is running and accessible. Retrying in 60 seconds.
2024-12-18 10:28:30.360 ERROR (SyncWorker_19) [homeassistant.components.influxdb] Cannot connect to InfluxDB due to 'HTTPConnectionPool(host='localhost', port=8086): Max retries exceeded with url: /write?db=home_assistant (Caused by NewConnectionError('<urllib3.connection.HTTPConnection object at 0x7a2a242bde50>: Failed to establish a new connection: [Errno 111] Connection refused'))'. Please check that the provided connection details (host, port, etc.) are correct and that your InfluxDB server is running and accessible. Retrying in 60 seconds.
2024-12-18 10:28:31.126 WARNING (MainThread) [homeassistant.components.automation.garage_hallway_motion_turns_light_on] Light - Garage Hallway Motion Turns Light On: Already running
2024-12-18 10:28:31.942 WARNING (MainThread) [homeassistant.components.automation.garage_hallway_motion_turns_light_on] Light - Garage Hallway Motion Turns Light On: Already running
2024-12-18 10:29:30.424 ERROR (SyncWorker_9) [homeassistant.components.influxdb] Cannot connect to InfluxDB due to 'HTTPConnectionPool(host='localhost', port=8086): Max retries exceeded with url: /write?db=home_assistant (Caused by NewConnectionError('<urllib3.connection.HTTPConnection object at 0x7a2a242bde50>: Failed to establish a new connection: [Errno 111] Connection refused'))'. Please check that the provided connection details (host, port, etc.) are correct and that your InfluxDB server is running and accessible. Retrying in 60 seconds.
2024-12-18 10:30:30.473 ERROR (SyncWorker_13) [homeassistant.components.influxdb] Cannot connect to InfluxDB due to 'HTTPConnectionPool(host='localhost', port=8086): Max retries exceeded with url: /write?db=home_assistant (Caused by NewConnectionError('<urllib3.connection.HTTPConnection object at 0x7a2a29cec230>: Failed to establish a new connection: [Errno 111] Connection refused'))'. Please check that the provided connection details (host, port, etc.) are correct and that your InfluxDB server is running and accessible. Retrying in 60 seconds.
2024-12-18 10:31:30.488 ERROR (SyncWorker_20) [homeassistant.components.influxdb] Cannot connect to InfluxDB due to 'HTTPConnectionPool(host='localhost', port=8086): Max retries exceeded with url: /write?db=home_assistant (Caused by NewConnectionError('<urllib3.connection.HTTPConnection object at 0x7a2a2c4ac410>: Failed to establish a new connection: [Errno 111] Connection refused'))'. Please check that the provided connection details (host, port, etc.) are correct and that your InfluxDB server is running and accessible. Retrying in 60 seconds.
2024-12-18 10:32:30.526 ERROR (SyncWorker_15) [homeassistant.components.influxdb] Cannot connect to InfluxDB due to 'HTTPConnectionPool(host='localhost', port=8086): Max retries exceeded with url: /write?db=home_assistant (Caused by NewConnectionError('<urllib3.connection.HTTPConnection object at 0x7a2a29ced220>: Failed to establish a new connection: [Errno 111] Connection refused'))'. Please check that the provided connection details (host, port, etc.) are correct and that your InfluxDB server is running and accessible. Retrying in 60 seconds.
2024-12-18 10:33:30.556 ERROR (SyncWorker_23) [homeassistant.components.influxdb] Cannot connect to InfluxDB due to 'HTTPConnectionPool(host='localhost', port=8086): Max retries exceeded with url: /write?db=home_assistant (Caused by NewConnectionError('<urllib3.connection.HTTPConnection object at 0x7a2a242be8a0>: Failed to establish a new connection: [Errno 111] Connection refused'))'. Please check that the provided connection details (host, port, etc.) are correct and that your InfluxDB server is running and accessible. Retrying in 60 seconds.
2024-12-18 10:34:30.600 ERROR (SyncWorker_1) [homeassistant.components.influxdb] Cannot connect to InfluxDB due to 'HTTPConnectionPool(host='localhost', port=8086): Max retries exceeded with url: /write?db=home_assistant (Caused by NewConnectionError('<urllib3.connection.HTTPConnection object at 0x7a2a242bcd70>: Failed to establish a new connection: [Errno 111] Connection refused'))'. Please check that the provided connection details (host, port, etc.) are correct and that your InfluxDB server is running and accessible. Retrying in 60 seconds.
