2024-12-19 00:56:37.148 WARNING (SyncWorker_0) [homeassistant.loader] We found a custom integration presence_simulation which has not been tested by Home Assistant. This component might cause stability problems, be sure to disable it if you experience issues with Home Assistant
2024-12-19 00:56:37.150 WARNING (SyncWorker_0) [homeassistant.loader] We found a custom integration iphonedetect which has not been tested by Home Assistant. This component might cause stability problems, be sure to disable it if you experience issues with Home Assistant
2024-12-19 00:56:37.151 WARNING (SyncWorker_0) [homeassistant.loader] We found a custom integration pirateweather which has not been tested by Home Assistant. This component might cause stability problems, be sure to disable it if you experience issues with Home Assistant
2024-12-19 00:56:37.153 WARNING (SyncWorker_0) [homeassistant.loader] We found a custom integration alexa_media which has not been tested by Home Assistant. This component might cause stability problems, be sure to disable it if you experience issues with Home Assistant
2024-12-19 00:56:37.155 WARNING (SyncWorker_0) [homeassistant.loader] We found a custom integration simple_wyze_vac which has not been tested by Home Assistant. This component might cause stability problems, be sure to disable it if you experience issues with Home Assistant
2024-12-19 00:56:37.156 WARNING (SyncWorker_0) [homeassistant.loader] We found a custom integration hacs which has not been tested by Home Assistant. This component might cause stability problems, be sure to disable it if you experience issues with Home Assistant
2024-12-19 00:56:37.158 WARNING (SyncWorker_0) [homeassistant.loader] We found a custom integration nws_alerts which has not been tested by Home Assistant. This component might cause stability problems, be sure to disable it if you experience issues with Home Assistant
2024-12-19 00:56:37.160 WARNING (SyncWorker_0) [homeassistant.loader] We found a custom integration gasbuddy which has not been tested by Home Assistant. This component might cause stability problems, be sure to disable it if you experience issues with Home Assistant
2024-12-19 00:56:37.162 WARNING (SyncWorker_0) [homeassistant.loader] We found a custom integration reolink_discovery which has not been tested by Home Assistant. This component might cause stability problems, be sure to disable it if you experience issues with Home Assistant
2024-12-19 00:56:37.165 WARNING (SyncWorker_0) [homeassistant.loader] We found a custom integration wyzeapi which has not been tested by Home Assistant. This component might cause stability problems, be sure to disable it if you experience issues with Home Assistant
2024-12-19 00:56:37.167 WARNING (SyncWorker_0) [homeassistant.loader] We found a custom integration auto_backup which has not been tested by Home Assistant. This component might cause stability problems, be sure to disable it if you experience issues with Home Assistant
2024-12-19 00:56:39.916 WARNING (Recorder) [homeassistant.components.recorder.util] The system could not validate that the sqlite3 database at //config/home-assistant_v2.db was shutdown cleanly
2024-12-19 00:56:39.979 WARNING (Recorder) [homeassistant.components.recorder.util] Ended unfinished session (id=208 from 2024-12-19 04:35:05.249916)
2024-12-19 00:57:00.898 ERROR (MainThread) [homeassistant.components.sensor] Platform smartthings does not generate unique IDs. ID 1a6d0984-19b4-426e-86d8-77906f2fe112.energy already exists - ignoring sensor.outlet_energy_meter
2024-12-19 00:57:00.899 ERROR (MainThread) [homeassistant.components.sensor] Platform smartthings does not generate unique IDs. ID 1a6d0984-19b4-426e-86d8-77906f2fe112.power already exists - ignoring sensor.outlet_power_meter
2024-12-19 00:57:12.840 WARNING (MainThread) [homeassistant.components.homeassistant.triggers.numeric_state] Error initializing 'Low Level Notifications' trigger: In 'numeric_state' condition: unknown entity sensor.southeast_corner_battery
2024-12-19 00:57:12.841 WARNING (MainThread) [homeassistant.components.homeassistant.triggers.numeric_state] Error initializing 'Low Level Notifications' trigger: In 'numeric_state' condition: unknown entity sensor.backyard_east_battery
2024-12-19 00:57:12.841 WARNING (MainThread) [homeassistant.components.homeassistant.triggers.numeric_state] Error initializing 'Low Level Notifications' trigger: In 'numeric_state' condition: unknown entity sensor.backyard_west_battery
2024-12-19 01:07:15.758 WARNING (MainThread) [alexapy.helpers] alexaapi.get_customer_history_records((<alexapy.alexalogin.AlexaLogin object at 0x7fa5e929c050>,), {'max_record_size': 10}): Timeout error occurred accessing AlexaAPI: An exception of type CancelledError occurred. Arguments:
()
2024-12-19 04:29:26.762 WARNING (MainThread) [alexapy.helpers] alexaapi.get_customer_history_records((<alexapy.alexalogin.AlexaLogin object at 0x7fa5e929c050>,), {'max_record_size': 10}): Timeout error occurred accessing AlexaAPI: An exception of type CancelledError occurred. Arguments:
()
2024-12-19 04:33:09.411 ERROR (Thread-11) [pychromecast.socket_client] [Basement TV(192.168.1.83):8009] Failed to connect to service HostServiceInfo(host='192.168.1.83', port=8009), retrying in 5.0s
2024-12-19 04:49:52.728 WARNING (MainThread) [alexapy.helpers] alexaapi.get_customer_history_records((<alexapy.alexalogin.AlexaLogin object at 0x7fa5e929c050>,), {'max_record_size': 10}): Timeout error occurred accessing AlexaAPI: An exception of type CancelledError occurred. Arguments:
()
2024-12-19 06:16:58.061 ERROR (MainThread) [homeassistant.components.accuweather.coordinator] Error fetching Home (observation) data: The allowed number of requests has been exceeded
2024-12-19 06:30:44.709 WARNING (MainThread) [alexapy.helpers] alexaapi.get_customer_history_records((<alexapy.alexalogin.AlexaLogin object at 0x7fa5e929c050>,), {'max_record_size': 10}): Timeout error occurred accessing AlexaAPI: An exception of type CancelledError occurred. Arguments:
()
2024-12-19 06:56:58.133 ERROR (MainThread) [homeassistant.components.accuweather.coordinator] Error fetching Home (daily forecast) data: The allowed number of requests has been exceeded
2024-12-19 07:31:28.691 WARNING (MainThread) [alexapy.helpers] alexaapi.get_customer_history_records((<alexapy.alexalogin.AlexaLogin object at 0x7fa5e929c050>,), {'max_record_size': 10}): Timeout error occurred accessing AlexaAPI: An exception of type CancelledError occurred. Arguments:
()
2024-12-19 08:35:41.269 WARNING (MainThread) [homeassistant.components.automation] Error evaluating condition in 'Light - Morning Lights Schedule':
In 'condition' (item 2 of 3):
  In 'state':
    In 'state' condition: unknown entity input_boolean.vacation_mode
In 'condition' (item 3 of 3):
  In 'state':
    In 'state' condition: unknown entity binary_sensor.workday_sensor
2024-12-19 09:12:44.736 WARNING (MainThread) [alexapy.helpers] alexaapi.get_customer_history_records((<alexapy.alexalogin.AlexaLogin object at 0x7fa5e929c050>,), {'max_record_size': 10}): Timeout error occurred accessing AlexaAPI: An exception of type CancelledError occurred. Arguments:
()
2024-12-19 09:41:46.128 WARNING (MainThread) [alexapy.helpers] alexaapi.get_customer_history_records((<alexapy.alexalogin.AlexaLogin object at 0x7fa5e929c050>,), {'max_record_size': 10}): Timeout error occurred accessing AlexaAPI: An exception of type CancelledError occurred. Arguments:
()
2024-12-19 10:03:44.310 WARNING (MainThread) [homeassistant.components.automation] Error evaluating condition in 'Lights - Evening Activation (Sunset or Low Light)':
In 'condition' (item 1 of 2):
  In 'state':
    In 'state' condition: unknown entity group.family
2024-12-19 10:15:53.443 WARNING (MainThread) [homeassistant.components.apple_tv] Connection lost to Apple TV "BasementFamilyRoom"
2024-12-19 10:16:13.373 ERROR (Thread-11) [pychromecast.socket_client] [Basement TV(192.168.1.83):8009] Failed to connect to service HostServiceInfo(host='192.168.1.83', port=8009), retrying in 5.0s
2024-12-19 10:16:32.317 ERROR (MainThread) [pyatv.protocols.airplay] Failed to set up remote control channel
Traceback (most recent call last):
  File "/usr/local/lib/python3.13/site-packages/pyatv/protocols/airplay/__init__.py", line 347, in _connect_rc
    await session.connect()
  File "/usr/local/lib/python3.13/site-packages/pyatv/protocols/airplay/ap2_session.py", line 70, in connect
    self.connection = await http_connect(self._address, self._control_port)
                      ^^^^^^^^^^^^^^^^^^^^^^^^^^^^^^^^^^^^^^^^^^^^^^^^^^^^^
  File "/usr/local/lib/python3.13/site-packages/pyatv/support/http.py", line 654, in http_connect
    _, connection = await loop.create_connection(HttpConnection, address, port)
                    ^^^^^^^^^^^^^^^^^^^^^^^^^^^^^^^^^^^^^^^^^^^^^^^^^^^^^^^^^^^
  File "/usr/local/lib/python3.13/asyncio/base_events.py", line 1155, in create_connection
    raise exceptions[0]
  File "/usr/local/lib/python3.13/asyncio/base_events.py", line 1137, in create_connection
    sock = await self._connect_sock(
           ^^^^^^^^^^^^^^^^^^^^^^^^^
        exceptions, addrinfo, laddr_infos)
        ^^^^^^^^^^^^^^^^^^^^^^^^^^^^^^^^^^
  File "/usr/local/lib/python3.13/asyncio/base_events.py", line 1040, in _connect_sock
    await self.sock_connect(sock, address)
  File "/usr/local/lib/python3.13/asyncio/selector_events.py", line 641, in sock_connect
    return await fut
           ^^^^^^^^^
  File "/usr/local/lib/python3.13/asyncio/selector_events.py", line 681, in _sock_connect_cb
    raise OSError(err, f'Connect call failed {address}')
OSError: [Errno 113] Connect call failed ('192.168.1.195', 7000)
2024-12-19 10:16:35.389 ERROR (MainThread) [homeassistant.components.apple_tv] Failed to connect
Traceback (most recent call last):
  File "/usr/src/homeassistant/homeassistant/components/apple_tv/__init__.py", line 223, in connect_once
    await self._connect_once(raise_missing_credentials)
  File "/usr/src/homeassistant/homeassistant/components/apple_tv/__init__.py", line 208, in _connect_once
    await self._connect(conf, raise_missing_credentials)
  File "/usr/src/homeassistant/homeassistant/components/apple_tv/__init__.py", line 328, in _connect
    self.atv = await connect(conf, self.hass.loop, session=session)
               ^^^^^^^^^^^^^^^^^^^^^^^^^^^^^^^^^^^^^^^^^^^^^^^^^^^^
  File "/usr/local/lib/python3.13/site-packages/pyatv/__init__.py", line 155, in connect
    await atv.connect()
  File "/usr/local/lib/python3.13/site-packages/pyatv/core/facade.py", line 723, in connect
    if await setup_data.connect():
       ^^^^^^^^^^^^^^^^^^^^^^^^^^
  File "/usr/local/lib/python3.13/site-packages/pyatv/protocols/companion/__init__.py", line 661, in _connect
    await api.connect()
  File "/usr/local/lib/python3.13/site-packages/pyatv/protocols/companion/api.py", line 151, in connect
    await self._protocol.start()
  File "/usr/local/lib/python3.13/site-packages/pyatv/protocols/companion/protocol.py", line 100, in start
    await self.connection.connect()
  File "/usr/local/lib/python3.13/site-packages/pyatv/protocols/companion/connection.py", line 81, in connect
    await self.loop.create_connection(lambda: self, self.host, self.port)
  File "/usr/local/lib/python3.13/asyncio/base_events.py", line 1155, in create_connection
    raise exceptions[0]
  File "/usr/local/lib/python3.13/asyncio/base_events.py", line 1137, in create_connection
    sock = await self._connect_sock(
           ^^^^^^^^^^^^^^^^^^^^^^^^^
        exceptions, addrinfo, laddr_infos)
        ^^^^^^^^^^^^^^^^^^^^^^^^^^^^^^^^^^
  File "/usr/local/lib/python3.13/asyncio/base_events.py", line 1040, in _connect_sock
    await self.sock_connect(sock, address)
  File "/usr/local/lib/python3.13/asyncio/selector_events.py", line 641, in sock_connect
    return await fut
           ^^^^^^^^^
  File "/usr/local/lib/python3.13/asyncio/selector_events.py", line 681, in _sock_connect_cb
    raise OSError(err, f'Connect call failed {address}')
OSError: [Errno 113] Connect call failed ('192.168.1.195', 49153)
2024-12-19 10:20:11.556 WARNING (MainThread) [homeassistant.components.automation.garage_hallway_motion_turns_light_on] Light - Garage Hallway Motion Turns Light On: Already running
2024-12-19 10:47:39.461 WARNING (Thread-16 (process_request_thread)) [pywemo.subscribe] Received event for unregistered device 192.168.1.67
2024-12-19 10:50:14.659 WARNING (Thread-18 (process_request_thread)) [pywemo.subscribe] Received event for unregistered device 192.168.1.67
2024-12-19 10:53:00.875 WARNING (Thread-20 (process_request_thread)) [pywemo.subscribe] Received event for unregistered device 192.168.1.67
2024-12-19 10:55:04.116 WARNING (Thread-22 (process_request_thread)) [pywemo.subscribe] Received event for unregistered device 192.168.1.67
2024-12-19 10:57:38.354 WARNING (Thread-24 (process_request_thread)) [pywemo.subscribe] Received event for unregistered device 192.168.1.67
2024-12-19 11:00:05.573 WARNING (Thread-26 (process_request_thread)) [pywemo.subscribe] Received event for unregistered device 192.168.1.67
2024-12-19 11:02:18.799 WARNING (Thread-28 (process_request_thread)) [pywemo.subscribe] Received event for unregistered device 192.168.1.67
2024-12-19 11:03:36.163 ERROR (MainThread) [homeassistant.components.sensor] Platform smartthings does not generate unique IDs. ID 1a6d0984-19b4-426e-86d8-77906f2fe112.energy already exists - ignoring sensor.outlet_energy_meter
2024-12-19 11:03:36.163 ERROR (MainThread) [homeassistant.components.sensor] Platform smartthings does not generate unique IDs. ID 1a6d0984-19b4-426e-86d8-77906f2fe112.power already exists - ignoring sensor.outlet_power_meter
2024-12-19 11:04:59.045 WARNING (Thread-31 (process_request_thread)) [pywemo.subscribe] Received event for unregistered device 192.168.1.67
2024-12-19 11:07:13.261 WARNING (Thread-33 (process_request_thread)) [pywemo.subscribe] Received event for unregistered device 192.168.1.67
