2024-12-23 09:26:39.457 WARNING (SyncWorker_0) [homeassistant.util.yaml.loader] YAML file /config/automations/notifications/severe_weather_alert.yaml contains duplicate key "platform". Check lines 8 and 10
2024-12-23 09:26:39.718 WARNING (SyncWorker_0) [homeassistant.loader] We found a custom integration presence_simulation which has not been tested by Home Assistant. This component might cause stability problems, be sure to disable it if you experience issues with Home Assistant
2024-12-23 09:26:39.720 WARNING (SyncWorker_0) [homeassistant.loader] We found a custom integration iphonedetect which has not been tested by Home Assistant. This component might cause stability problems, be sure to disable it if you experience issues with Home Assistant
2024-12-23 09:26:39.724 WARNING (SyncWorker_0) [homeassistant.loader] We found a custom integration pirateweather which has not been tested by Home Assistant. This component might cause stability problems, be sure to disable it if you experience issues with Home Assistant
2024-12-23 09:26:39.725 WARNING (SyncWorker_0) [homeassistant.loader] We found a custom integration alexa_media which has not been tested by Home Assistant. This component might cause stability problems, be sure to disable it if you experience issues with Home Assistant
2024-12-23 09:26:39.727 WARNING (SyncWorker_0) [homeassistant.loader] We found a custom integration simple_wyze_vac which has not been tested by Home Assistant. This component might cause stability problems, be sure to disable it if you experience issues with Home Assistant
2024-12-23 09:26:39.728 WARNING (SyncWorker_0) [homeassistant.loader] We found a custom integration hacs which has not been tested by Home Assistant. This component might cause stability problems, be sure to disable it if you experience issues with Home Assistant
2024-12-23 09:26:39.730 WARNING (SyncWorker_0) [homeassistant.loader] We found a custom integration nws_alerts which has not been tested by Home Assistant. This component might cause stability problems, be sure to disable it if you experience issues with Home Assistant
2024-12-23 09:26:39.733 WARNING (SyncWorker_0) [homeassistant.loader] We found a custom integration gasbuddy which has not been tested by Home Assistant. This component might cause stability problems, be sure to disable it if you experience issues with Home Assistant
2024-12-23 09:26:39.735 WARNING (SyncWorker_0) [homeassistant.loader] We found a custom integration reolink_discovery which has not been tested by Home Assistant. This component might cause stability problems, be sure to disable it if you experience issues with Home Assistant
2024-12-23 09:26:39.736 WARNING (SyncWorker_0) [homeassistant.loader] We found a custom integration wyzeapi which has not been tested by Home Assistant. This component might cause stability problems, be sure to disable it if you experience issues with Home Assistant
2024-12-23 09:26:39.739 WARNING (SyncWorker_0) [homeassistant.loader] We found a custom integration auto_backup which has not been tested by Home Assistant. This component might cause stability problems, be sure to disable it if you experience issues with Home Assistant
2024-12-23 09:26:49.900 ERROR (MainThread) [homeassistant.config] Invalid config for 'group' at groups.yaml, line 43: Entity ID brian_phone is an invalid entity ID for dictionary value 'group->all_devices->entities', got ['brian_phone', 'kathryn_phone', 'graham_phone', 'madelyn_phone'], please check the docs at https://www.home-assistant.io/integrations/group
2024-12-23 09:26:49.900 ERROR (MainThread) [homeassistant.setup] Setup failed for 'group': Invalid config.
2024-12-23 09:27:24.190 ERROR (MainThread) [homeassistant.components.sensor] Platform smartthings does not generate unique IDs. ID 1a6d0984-19b4-426e-86d8-77906f2fe112.energy already exists - ignoring sensor.outlet_energy_meter
2024-12-23 09:27:24.190 ERROR (MainThread) [homeassistant.components.sensor] Platform smartthings does not generate unique IDs. ID 1a6d0984-19b4-426e-86d8-77906f2fe112.power already exists - ignoring sensor.outlet_power_meter
2024-12-23 09:27:28.656 WARNING (MainThread) [homeassistant.components.homeassistant.triggers.numeric_state] Error initializing 'Low Level Notifications' trigger: In 'numeric_state' condition: unknown entity sensor.southeast_corner_battery
2024-12-23 09:27:28.656 WARNING (MainThread) [homeassistant.components.homeassistant.triggers.numeric_state] Error initializing 'Low Level Notifications' trigger: In 'numeric_state' condition: unknown entity sensor.backyard_east_battery
2024-12-23 09:27:28.656 WARNING (MainThread) [homeassistant.components.homeassistant.triggers.numeric_state] Error initializing 'Low Level Notifications' trigger: In 'numeric_state' condition: unknown entity sensor.backyard_west_battery
2024-12-23 09:28:00.486 WARNING (MainThread) [homeassistant.components.automation] Error evaluating condition in 'Water Leak Detection':
In 'condition':
  In 'state':
    In 'state' condition: unknown entity group.water_leak_sensors
2024-12-23 09:29:00.486 WARNING (MainThread) [homeassistant.components.automation] Error evaluating condition in 'Water Leak Detection':
In 'condition':
  In 'state':
    In 'state' condition: unknown entity group.water_leak_sensors
2024-12-23 09:30:00.487 WARNING (MainThread) [homeassistant.components.automation] Error evaluating condition in 'Water Leak Detection':
In 'condition':
  In 'state':
    In 'state' condition: unknown entity group.water_leak_sensors
2024-12-23 09:31:00.486 WARNING (MainThread) [homeassistant.components.automation] Error evaluating condition in 'Water Leak Detection':
In 'condition':
  In 'state':
    In 'state' condition: unknown entity group.water_leak_sensors
2024-12-23 09:32:00.485 WARNING (MainThread) [homeassistant.components.automation] Error evaluating condition in 'Water Leak Detection':
In 'condition':
  In 'state':
    In 'state' condition: unknown entity group.water_leak_sensors
2024-12-23 09:33:00.486 WARNING (MainThread) [homeassistant.components.automation] Error evaluating condition in 'Water Leak Detection':
In 'condition':
  In 'state':
    In 'state' condition: unknown entity group.water_leak_sensors
2024-12-23 09:34:00.486 WARNING (MainThread) [homeassistant.components.automation] Error evaluating condition in 'Water Leak Detection':
In 'condition':
  In 'state':
    In 'state' condition: unknown entity group.water_leak_sensors
2024-12-23 09:35:00.486 WARNING (MainThread) [homeassistant.components.automation] Error evaluating condition in 'Water Leak Detection':
In 'condition':
  In 'state':
    In 'state' condition: unknown entity group.water_leak_sensors
2024-12-23 09:36:00.487 WARNING (MainThread) [homeassistant.components.automation] Error evaluating condition in 'Water Leak Detection':
In 'condition':
  In 'state':
    In 'state' condition: unknown entity group.water_leak_sensors
2024-12-23 09:37:00.486 WARNING (MainThread) [homeassistant.components.automation] Error evaluating condition in 'Water Leak Detection':
In 'condition':
  In 'state':
    In 'state' condition: unknown entity group.water_leak_sensors
2024-12-23 09:37:41.702 WARNING (MainThread) [alexapy.helpers] alexaapi.get_customer_history_records((<alexapy.alexalogin.AlexaLogin object at 0x7049e8780d70>,), {'max_record_size': 10}): Timeout error occurred accessing AlexaAPI: An exception of type CancelledError occurred. Arguments:
()
2024-12-23 09:38:00.485 WARNING (MainThread) [homeassistant.components.automation] Error evaluating condition in 'Water Leak Detection':
In 'condition':
  In 'state':
    In 'state' condition: unknown entity group.water_leak_sensors
2024-12-23 09:39:00.485 WARNING (MainThread) [homeassistant.components.automation] Error evaluating condition in 'Water Leak Detection':
In 'condition':
  In 'state':
    In 'state' condition: unknown entity group.water_leak_sensors
2024-12-23 09:40:00.486 WARNING (MainThread) [homeassistant.components.automation] Error evaluating condition in 'Water Leak Detection':
In 'condition':
  In 'state':
    In 'state' condition: unknown entity group.water_leak_sensors
2024-12-23 09:41:00.486 WARNING (MainThread) [homeassistant.components.automation] Error evaluating condition in 'Water Leak Detection':
In 'condition':
  In 'state':
    In 'state' condition: unknown entity group.water_leak_sensors
2024-12-23 09:42:00.487 WARNING (MainThread) [homeassistant.components.automation] Error evaluating condition in 'Water Leak Detection':
In 'condition':
  In 'state':
    In 'state' condition: unknown entity group.water_leak_sensors
2024-12-23 09:42:23.635 ERROR (MainThread) [wyzeapy.services.update_manager] Unknown error happened during updating device info
Traceback (most recent call last):
  File "/usr/local/lib/python3.13/site-packages/wyzeapy/services/update_manager.py", line 42, in update
    self.device = await self.service.update(self.device)
                  ^^^^^^^^^^^^^^^^^^^^^^^^^^^^^^^^^^^^^^
  File "/usr/local/lib/python3.13/site-packages/wyzeapy/services/bulb_service.py", line 71, in update
    device_info = await self._get_property_list(bulb)
                  ^^^^^^^^^^^^^^^^^^^^^^^^^^^^^^^^^^^
  File "/usr/local/lib/python3.13/site-packages/wyzeapy/services/base_service.py", line 164, in _get_property_list
    response_json = await self._auth_lib.post("https://api.wyzecam.com/app/v2/device/get_property_list",
                    ^^^^^^^^^^^^^^^^^^^^^^^^^^^^^^^^^^^^^^^^^^^^^^^^^^^^^^^^^^^^^^^^^^^^^^^^^^^^^^^^^^^^
                                              json=payload)
                                              ^^^^^^^^^^^^^
  File "/usr/local/lib/python3.13/site-packages/wyzeapy/wyze_auth_lib.py", line 256, in post
    response = await _session.post(url, json=json, headers=headers, data=data)
               ^^^^^^^^^^^^^^^^^^^^^^^^^^^^^^^^^^^^^^^^^^^^^^^^^^^^^^^^^^^^^^^
  File "/usr/local/lib/python3.13/site-packages/aiohttp/client.py", line 703, in _request
    conn = await self._connector.connect(
           ^^^^^^^^^^^^^^^^^^^^^^^^^^^^^^
        req, traces=traces, timeout=real_timeout
        ^^^^^^^^^^^^^^^^^^^^^^^^^^^^^^^^^^^^^^^^
    )
    ^
  File "/usr/local/lib/python3.13/site-packages/aiohttp/connector.py", line 548, in connect
    proto = await self._create_connection(req, traces, timeout)
            ^^^^^^^^^^^^^^^^^^^^^^^^^^^^^^^^^^^^^^^^^^^^^^^^^^^
  File "/usr/local/lib/python3.13/site-packages/aiohttp/connector.py", line 1056, in _create_connection
    _, proto = await self._create_direct_connection(req, traces, timeout)
               ^^^^^^^^^^^^^^^^^^^^^^^^^^^^^^^^^^^^^^^^^^^^^^^^^^^^^^^^^^
  File "/usr/local/lib/python3.13/site-packages/aiohttp/connector.py", line 1369, in _create_direct_connection
    transp, proto = await self._wrap_create_connection(
                    ^^^^^^^^^^^^^^^^^^^^^^^^^^^^^^^^^^^
    ...<7 lines>...
    )
    ^
  File "/usr/local/lib/python3.13/site-packages/aiohttp/connector.py", line 1122, in _wrap_create_connection
    return await self._loop.create_connection(*args, **kwargs, sock=sock)
           ^^^^^^^^^^^^^^^^^^^^^^^^^^^^^^^^^^^^^^^^^^^^^^^^^^^^^^^^^^^^^^
  File "/usr/local/lib/python3.13/asyncio/base_events.py", line 1182, in create_connection
    transport, protocol = await self._create_connection_transport(
                          ^^^^^^^^^^^^^^^^^^^^^^^^^^^^^^^^^^^^^^^^
    ...<2 lines>...
        ssl_shutdown_timeout=ssl_shutdown_timeout)
        ^^^^^^^^^^^^^^^^^^^^^^^^^^^^^^^^^^^^^^^^^^
  File "/usr/local/lib/python3.13/asyncio/base_events.py", line 1215, in _create_connection_transport
    await waiter
asyncio.exceptions.CancelledError: Final process shutdown
2024-12-23 09:42:28.635 WARNING (MainThread) [homeassistant.runner] Task could not be canceled and was still running after shutdown: <Task cancelling name='Task-587' coro=<UpdateManager.update_next() running at /usr/local/lib/python3.13/site-packages/wyzeapy/services/update_manager.py:95> wait_for=<Future pending cb=[Task.task_wakeup()]>>
